{"metrics":{"dashboard_error":"対象のコンピューターによって拒否されたため、接続できませんでした。 (localhost:5000)","memory_percent":19.79,"database_size_mb":0,"python_processes":18,"memory_used_gb":25.32,"log_files_size_mb":2.04,"dashboard_response_code":0,"check_duration_ms":8625.07,"disk_percent":42.98,"disk_free_gb":530.68,"python_memory_mb":657.76,"log_files_count":4,"timestamp":"2025-10-07T13:43:01Z","memory_total_gb":127.92,"cpu_percent":9.0,"disk_total_gb":930.64,"database_status":"MISSING","dashboard_status":"ERROR"},"health":{"alerts":["ダッシュボードが応答しません: 対象のコンピューターによって拒否されたため、接続できませんでした。 (localhost:5000)","データベースファイルが見つかりません"],"warnings":[],"overall_status":"CRITICAL"},"timestamp":"2025-10-07T13:43:01Z"}
